WARNING 2015-03-04 15:54:39 C:\Python27\lib\site-packages\django-1.6.5-py2.7.egg\django\core\handlers\base.py base 143 Not Found: / status_code:404
WARNING 2015-03-04 15:54:39 C:\Python27\lib\site-packages\django-1.6.5-py2.7.egg\django\core\handlers\base.py base 143 Not Found: /favicon.ico status_code:404
ERROR 2015-03-04 15:54:45 C:\Python27\lib\site-packages\django-1.6.5-py2.7.egg\django\core\handlers\base.py base 224 Internal Server Error: /admin/ status_code:500
Traceback (most recent call last):
  File "C:\Python27\lib\site-packages\django-1.6.5-py2.7.egg\django\core\handlers\base.py", line 112, in get_response
    response = wrapped_callback(request, *callback_args, **callback_kwargs)
  File "C:\Python27\lib\site-packages\django-1.6.5-py2.7.egg\django\contrib\admin\sites.py", line 215, in wrapper
    return self.admin_view(view, cacheable)(*args, **kwargs)
  File "C:\Python27\lib\site-packages\django-1.6.5-py2.7.egg\django\utils\decorators.py", line 99, in _wrapped_view
    response = view_func(request, *args, **kwargs)
  File "C:\Python27\lib\site-packages\django-1.6.5-py2.7.egg\django\views\decorators\cache.py", line 52, in _wrapped_view_func
    response = view_func(request, *args, **kwargs)
  File "C:\Python27\lib\site-packages\django-1.6.5-py2.7.egg\django\contrib\admin\sites.py", line 194, in inner
    current_app=self.name):
  File "C:\Python27\lib\site-packages\django-1.6.5-py2.7.egg\django\core\urlresolvers.py", line 503, in reverse
    app_list = resolver.app_dict[ns]
  File "C:\Python27\lib\site-packages\django-1.6.5-py2.7.egg\django\core\urlresolvers.py", line 329, in app_dict
    self._populate()
  File "C:\Python27\lib\site-packages\django-1.6.5-py2.7.egg\django\core\urlresolvers.py", line 290, in _populate
    for name in pattern.reverse_dict:
  File "C:\Python27\lib\site-packages\django-1.6.5-py2.7.egg\django\core\urlresolvers.py", line 315, in reverse_dict
    self._populate()
  File "C:\Python27\lib\site-packages\django-1.6.5-py2.7.egg\django\core\urlresolvers.py", line 267, in _populate
    for pattern in reversed(self.url_patterns):
  File "C:\Python27\lib\site-packages\django-1.6.5-py2.7.egg\django\core\urlresolvers.py", line 369, in url_patterns
    raise ImproperlyConfigured("The included urlconf %s doesn't have any patterns in it" % self.urlconf_name)
ImproperlyConfigured: The included urlconf <module 'XTest.urls' from 'F:\python\MATMS\MATMS\XTest\urls.py'> doesn't have any patterns in it
WARNING 2015-03-04 15:58:18 C:\Python27\lib\site-packages\django-1.6.5-py2.7.egg\django\core\handlers\base.py base 143 Not Found: / status_code:404
WARNING 2015-03-04 16:03:48 C:\Python27\lib\site-packages\django-1.6.5-py2.7.egg\django\core\handlers\base.py base 143 Not Found: /favicon.ico status_code:404
WARNING 2015-03-04 16:03:51 C:\Python27\lib\site-packages\django-1.6.5-py2.7.egg\django\core\handlers\base.py base 143 Not Found: /favicon.ico status_code:404
WARNING 2015-03-04 16:05:15 C:\Python27\lib\site-packages\django-1.6.5-py2.7.egg\django\core\handlers\base.py base 143 Not Found: /ATMS status_code:404
WARNING 2015-03-04 16:05:37 C:\Python27\lib\site-packages\django-1.6.5-py2.7.egg\django\core\handlers\base.py base 143 Not Found: /static/css/bootstrap.min.css status_code:404
